<?xml version="1.0" ?>
<!-- =================================================================================== -->
<!-- |    This document was autogenerated by xacro from ur3ar10.urdf.xacro             | -->
<!-- |    EDITING THIS FILE BY HAND IS NOT RECOMMENDED                                 | -->
<!-- =================================================================================== -->
<robot name="ur3_ar10" xmlns:xacro="http://www.ros.org/wiki/xacro">
  <gazebo>
    <plugin filename="libgazebo_ros_control.so" name="ros_control">
      <!--robotNamespace>/</robotNamespace-->
      <!--robotSimType>gazebo_ros_control/DefaultRobotHWSim</robotSimType-->
    </plugin>
    <!--
    <plugin name="gazebo_ros_power_monitor_controller" filename="libgazebo_ros_power_monitor.so">
      <alwaysOn>true</alwaysOn>
      <updateRate>1.0</updateRate>
      <timeout>5</timeout>
      <powerStateTopic>power_state</powerStateTopic>
      <powerStateRate>10.0</powerStateRate>
      <fullChargeCapacity>87.78</fullChargeCapacity>     
      <dischargeRate>-474</dischargeRate>
      <chargeRate>525</chargeRate>
      <dischargeVoltage>15.52</dischargeVoltage>
      <chargeVoltage>16.41</chargeVoltage>
    </plugin>
-->
  </gazebo>
  <!--
  Author: Felix Messmer
-->
  <!-- measured from model -->
  <link name="base_link">
    <visual>
      <geometry>
        <mesh filename="package://ur_description/meshes/ur3/visual/base.dae"/>
      </geometry>
      <material name="LightGrey">
        <color rgba="0.7 0.7 0.7 1.0"/>
      </material>
    </visual>
    <collision>
      <geometry>
        <mesh filename="package://ur_description/meshes/ur3/collision/base.stl"/>
      </geometry>
    </collision>
    <inertial>
      <mass value="2.0"/>
      <origin rpy="0 0 0" xyz="0.0 0.0 0.0"/>
      <inertia ixx="0.0030531654454" ixy="0.0" ixz="0.0" iyy="0.0030531654454" iyz="0.0" izz="0.005625"/>
    </inertial>
  </link>
  <joint name="shoulder_pan_joint" type="revolute">
    <parent link="base_link"/>
    <child link="shoulder_link"/>
    <origin rpy="0.0 0.0 0.0" xyz="0.0 0.0 0.1519"/>
    <axis xyz="0 0 1"/>
    <limit effort="330.0" lower="-1.57079632679" upper="1.57079632679" velocity="2.16"/>
    <dynamics damping="0.0" friction="0.0"/>
  </joint>
  <link name="shoulder_link">
    <visual>
      <geometry>
        <mesh filename="package://ur_description/meshes/ur3/visual/shoulder.dae"/>
      </geometry>
      <material name="LightGrey">
        <color rgba="0.7 0.7 0.7 1.0"/>
      </material>
    </visual>
    <collision>
      <geometry>
        <mesh filename="package://ur_description/meshes/ur3/collision/shoulder.stl"/>
      </geometry>
    </collision>
    <inertial>
      <mass value="2.0"/>
      <origin rpy="0 0 0" xyz="0.0 0.0 0.0"/>
      <inertia ixx="0.0080931634294" ixy="0.0" ixz="0.0" iyy="0.0080931634294" iyz="0.0" izz="0.005625"/>
    </inertial>
  </link>
  <joint name="shoulder_lift_joint" type="revolute">
    <parent link="shoulder_link"/>
    <child link="upper_arm_link"/>
    <origin rpy="0.0 1.57079632679 0.0" xyz="0.0 0.1198 0.0"/>
    <axis xyz="0 1 0"/>
    <limit effort="330.0" lower="-3.14159265359" upper="3.14159265359" velocity="2.16"/>
    <dynamics damping="0.0" friction="0.0"/>
  </joint>
  <link name="upper_arm_link">
    <visual>
      <geometry>
        <mesh filename="package://ur_description/meshes/ur3/visual/upperarm.dae"/>
      </geometry>
      <material name="LightGrey">
        <color rgba="0.7 0.7 0.7 1.0"/>
      </material>
    </visual>
    <collision>
      <geometry>
        <mesh filename="package://ur_description/meshes/ur3/collision/upperarm.stl"/>
      </geometry>
    </collision>
    <inertial>
      <mass value="3.42"/>
      <origin rpy="0 0 0" xyz="0.0 0.0 0.121825"/>
      <inertia ixx="0.0217284832211" ixy="0.0" ixz="0.0" iyy="0.0217284832211" iyz="0.0" izz="0.00961875"/>
    </inertial>
  </link>
  <joint name="elbow_joint" type="revolute">
    <parent link="upper_arm_link"/>
    <child link="forearm_link"/>
    <origin rpy="0.0 0.0 0.0" xyz="0.0 -0.0925 0.24365"/>
    <axis xyz="0 1 0"/>
    <limit effort="150.0" lower="-3.14159265359" upper="3.14159265359" velocity="3.15"/>
    <dynamics damping="0.0" friction="0.0"/>
  </joint>
  <link name="forearm_link">
    <visual>
      <geometry>
        <mesh filename="package://ur_description/meshes/ur3/visual/forearm.dae"/>
      </geometry>
      <material name="LightGrey">
        <color rgba="0.7 0.7 0.7 1.0"/>
      </material>
    </visual>
    <collision>
      <geometry>
        <mesh filename="package://ur_description/meshes/ur3/collision/forearm.stl"/>
      </geometry>
    </collision>
    <inertial>
      <mass value="1.26"/>
      <origin rpy="0 0 0" xyz="0.0 0.0 0.106625"/>
      <inertia ixx="0.00654680644378" ixy="0.0" ixz="0.0" iyy="0.00654680644378" iyz="0.0" izz="0.00354375"/>
    </inertial>
  </link>
  <joint name="wrist_1_joint" type="revolute">
    <parent link="forearm_link"/>
    <child link="wrist_1_link"/>
    <origin rpy="0.0 1.57079632679 0.0" xyz="0.0 0.0 0.21325"/>
    <axis xyz="0 1 0"/>
    <limit effort="54.0" lower="-3.14159265359" upper="3.14159265359" velocity="3.2"/>
    <dynamics damping="0.0" friction="0.0"/>
  </joint>
  <link name="wrist_1_link">
    <visual>
      <geometry>
        <mesh filename="package://ur_description/meshes/ur3/visual/wrist1.dae"/>
      </geometry>
      <material name="LightGrey">
        <color rgba="0.7 0.7 0.7 1.0"/>
      </material>
    </visual>
    <collision>
      <geometry>
        <mesh filename="package://ur_description/meshes/ur3/collision/wrist1.stl"/>
      </geometry>
    </collision>
    <inertial>
      <mass value="0.8"/>
      <origin rpy="0 0 0" xyz="0.0 0.0 0.0"/>
      <inertia ixx="0.002084999166" ixy="0.0" ixz="0.0" iyy="0.002084999166" iyz="0.0" izz="0.00225"/>
    </inertial>
  </link>
  <joint name="wrist_2_joint" type="revolute">
    <parent link="wrist_1_link"/>
    <child link="wrist_2_link"/>
    <origin rpy="0.0 0.0 0.0" xyz="0.0 0.08505 0.0"/>
    <axis xyz="0 0 1"/>
    <limit effort="54.0" lower="-3.14159265359" upper="3.14159265359" velocity="3.2"/>
    <dynamics damping="0.0" friction="0.0"/>
  </joint>
  <link name="wrist_2_link">
    <visual>
      <geometry>
        <mesh filename="package://ur_description/meshes/ur3/visual/wrist2.dae"/>
      </geometry>
      <material name="LightGrey">
        <color rgba="0.7 0.7 0.7 1.0"/>
      </material>
    </visual>
    <collision>
      <geometry>
        <mesh filename="package://ur_description/meshes/ur3/collision/wrist2.stl"/>
      </geometry>
    </collision>
    <inertial>
      <mass value="0.8"/>
      <origin rpy="0 0 0" xyz="0.0 0.0 0.0"/>
      <inertia ixx="0.002084999166" ixy="0.0" ixz="0.0" iyy="0.002084999166" iyz="0.0" izz="0.00225"/>
    </inertial>
  </link>
  <joint name="wrist_3_joint" type="revolute">
    <parent link="wrist_2_link"/>
    <child link="wrist_3_link"/>
    <origin rpy="0.0 0.0 0.0" xyz="0.0 0.0 0.08535"/>
    <axis xyz="0 1 0"/>
    <limit effort="54.0" lower="-3.14159265359" upper="3.14159265359" velocity="3.2"/>
    <dynamics damping="0.0" friction="0.0"/>
  </joint>
  <link name="wrist_3_link">
    <visual>
      <geometry>
        <mesh filename="package://ur_description/meshes/ur3/visual/wrist3.dae"/>
      </geometry>
      <material name="LightGrey">
        <color rgba="0.7 0.7 0.7 1.0"/>
      </material>
    </visual>
    <collision>
      <geometry>
        <mesh filename="package://ur_description/meshes/ur3/collision/wrist3.stl"/>
      </geometry>
    </collision>
    <inertial>
      <mass value="0.35"/>
      <origin rpy="0 0 0" xyz="0.0 0.0 0.0"/>
      <inertia ixx="0.000912187135125" ixy="0.0" ixz="0.0" iyy="0.000912187135125" iyz="0.0" izz="0.000984375"/>
    </inertial>
  </link>
  <joint name="ee_fixed_joint" type="fixed">
    <parent link="wrist_3_link"/>
    <child link="ee_link"/>
    <origin rpy="0.0 0.0 1.57079632679" xyz="0.0 0.0819 0.0"/>
  </joint>
  <link name="ee_link">
    <collision>
      <geometry>
        <box size="0.01 0.01 0.01"/>
      </geometry>
      <origin rpy="0 0 0" xyz="-0.01 0 0"/>
    </collision>
  </link>
  <transmission name="shoulder_pan_trans">
    <type>transmission_interface/SimpleTransmission</type>
    <joint name="shoulder_pan_joint">
      <hardwareInterface>hardware_interface/PositionJointInterface</hardwareInterface>
    </joint>
    <actuator name="shoulder_pan_motor">
      <mechanicalReduction>1</mechanicalReduction>
    </actuator>
  </transmission>
  <transmission name="shoulder_lift_trans">
    <type>transmission_interface/SimpleTransmission</type>
    <joint name="shoulder_lift_joint">
      <hardwareInterface>hardware_interface/PositionJointInterface</hardwareInterface>
    </joint>
    <actuator name="shoulder_lift_motor">
      <mechanicalReduction>1</mechanicalReduction>
    </actuator>
  </transmission>
  <transmission name="elbow_trans">
    <type>transmission_interface/SimpleTransmission</type>
    <joint name="elbow_joint">
      <hardwareInterface>hardware_interface/PositionJointInterface</hardwareInterface>
    </joint>
    <actuator name="elbow_motor">
      <mechanicalReduction>1</mechanicalReduction>
    </actuator>
  </transmission>
  <transmission name="wrist_1_trans">
    <type>transmission_interface/SimpleTransmission</type>
    <joint name="wrist_1_joint">
      <hardwareInterface>hardware_interface/PositionJointInterface</hardwareInterface>
    </joint>
    <actuator name="wrist_1_motor">
      <mechanicalReduction>1</mechanicalReduction>
    </actuator>
  </transmission>
  <transmission name="wrist_2_trans">
    <type>transmission_interface/SimpleTransmission</type>
    <joint name="wrist_2_joint">
      <hardwareInterface>hardware_interface/PositionJointInterface</hardwareInterface>
    </joint>
    <actuator name="wrist_2_motor">
      <mechanicalReduction>1</mechanicalReduction>
    </actuator>
  </transmission>
  <transmission name="wrist_3_trans">
    <type>transmission_interface/SimpleTransmission</type>
    <joint name="wrist_3_joint">
      <hardwareInterface>hardware_interface/PositionJointInterface</hardwareInterface>
    </joint>
    <actuator name="wrist_3_motor">
      <mechanicalReduction>1</mechanicalReduction>
    </actuator>
  </transmission>
  <gazebo reference="shoulder_link">
    <selfCollide>true</selfCollide>
  </gazebo>
  <gazebo reference="upper_arm_link">
    <selfCollide>true</selfCollide>
  </gazebo>
  <gazebo reference="forearm_link">
    <selfCollide>true</selfCollide>
  </gazebo>
  <gazebo reference="wrist_1_link">
    <selfCollide>true</selfCollide>
  </gazebo>
  <gazebo reference="wrist_3_link">
    <selfCollide>true</selfCollide>
  </gazebo>
  <gazebo reference="wrist_2_link">
    <selfCollide>true</selfCollide>
  </gazebo>
  <gazebo reference="ee_link">
    <selfCollide>true</selfCollide>
  </gazebo>
  <!-- ROS base_link to UR 'Base' Coordinates transform -->
  <link name="base"/>
  <joint name="base_link-base_fixed_joint" type="fixed">
    <!-- NOTE: this rotation is only needed as long as base_link itself is
                 not corrected wrt the real robot (ie: rotated over 180
                 degrees)
      -->
    <origin rpy="0 0 -3.14159265359" xyz="0 0 0"/>
    <parent link="base_link"/>
    <child link="base"/>
  </joint>
  <!-- Frame coincident with all-zeros TCP on UR controller -->
  <link name="tool0"/>
  <joint name="wrist_3_link-tool0_fixed_joint" type="fixed">
    <origin rpy="-1.57079632679 0 0" xyz="0 0.0819 0"/>
    <parent link="wrist_3_link"/>
    <child link="tool0"/>
  </joint>
  <!--robot name="ar10"> -->
  <link name="wrist_plate">
    <visual>
      <geometry>
        <cylinder length="0.002" radius="0.06"/>
      </geometry>
      <material name="blue">
        <color rgba=".1 .3 .6 1"/>
      </material>
    </visual>
    <collision>
      <geometry>
        <cylinder length="0.002" radius="0.06"/>
      </geometry>
    </collision>
  </link>
  <!--****************MY editing************************* -->
  <joint name="wrist2ee_link" type="fixed">
    <parent link="ee_link"/>
    <child link="wrist_plate"/>
    <origin rpy="0.0 1.57 0.0" xyz="0.008 0.0 0.0"/>
  </joint>
  <link name="circuit_support">
    <visual>
      <geometry>
        <box size="0.0555 0.0555 0.05"/>
      </geometry>
      <origin xyz="0 0 0"/>
      <material name="black">
        <color rgba=".1 .1 .1 1"/>
      </material>
    </visual>
    <collision>
      <geometry>
        <box size="0.0555 0.0555 0.05"/>
      </geometry>
    </collision>
    <inertial>
      <mass value="1"/>
      <inertia ixx="0.4" ixy="0.0" ixz="0.0" iyy="0.4" iyz="0.0" izz="0.2"/>
    </inertial>
  </link>
  <joint name="wrist_plate_to_circuit_support" type="fixed">
    <parent link="wrist_plate"/>
    <child link="circuit_support"/>
    <origin xyz="0 0 .026"/>
  </joint>
   define palm1 parameters
  
   define palm2 parameters
  
   define knuckle 1 parameters
  
   define knuckle 2 parameters
  
   define knuckle 3 parameters
  
   define knuckle 4 parameters

  
  <link name="palm1">
    <visual>
      <geometry>
        <box size="0.0555 0.002 0.0463"/>
      </geometry>
      <origin xyz="0 0 0"/>
      <material name="blue">
      </material>
    </visual>
    <collision>
      <geometry>
        <box size="0.0555 0.002 0.0463"/>
      </geometry>
    </collision>
    <inertial>
      <mass value="1"/>
      <inertia ixx="0.4" ixy="0.0" ixz="0.0" iyy="0.4" iyz="0.0" izz="0.2"/>
    </inertial>
  </link>
  <joint name="circuit_support_to_palm1" type="fixed">
    <parent link="circuit_support"/>
    <child link="palm1"/>
    <origin xyz="0 .015 .04815"/>
  </joint>
  <link name="palm2">
    <visual>
      <geometry>
        <box size="0.084 0.002 0.025"/>
      </geometry>
      <origin xyz="0 0 0"/>
      <material name="blue">
      </material>
    </visual>
    <collision>
      <geometry>
        <box size="0.084 0.002 0.025"/>
      </geometry>
    </collision>
    <inertial>
      <mass value="1"/>
      <inertia ixx="0.4" ixy="0.0" ixz="0.0" iyy="0.4" iyz="0.0" izz="0.2"/>
    </inertial>
  </link>
  <joint name="palm1_to_palm2" type="fixed">
    <parent link="palm1"/>
    <child link="palm2"/>
    <origin xyz="-.01425 0 .02315"/>
  </joint>
  <link name="knuckle1">
    <visual>
      <geometry>
        <box size="0.018 0.0095 0.003"/>
      </geometry>
      <origin xyz="0 0 0"/>
      <material name="blue">
      </material>
    </visual>
    <collision>
      <geometry>
        <box size="0.018 0.0095 0.003"/>
      </geometry>
    </collision>
    <inertial>
      <mass value="1"/>
      <inertia ixx="0.4" ixy="0.0" ixz="0.0" iyy="0.4" iyz="0.0" izz="0.2"/>
    </inertial>
  </link>
  <joint name="palm2_to_knuckle1" type="fixed">
    <parent link="palm2"/>
    <child link="knuckle1"/>
    <origin xyz="0.0315 -.00375 .014"/>
  </joint>
  <link name="knuckle2">
    <visual>
      <geometry>
        <box size="0.018 0.0095 0.01"/>
      </geometry>
      <origin xyz="0 0 0"/>
      <material name="blue">
      </material>
    </visual>
    <collision>
      <geometry>
        <box size="0.018 0.0095 0.01"/>
      </geometry>
    </collision>
    <inertial>
      <mass value="1"/>
      <inertia ixx="0.4" ixy="0.0" ixz="0.0" iyy="0.4" iyz="0.0" izz="0.2"/>
    </inertial>
  </link>
  <joint name="palm2_to_knuckle2" type="fixed">
    <parent link="palm2"/>
    <child link="knuckle2"/>
    <origin xyz="0.0105 -.00375 .0175"/>
  </joint>
  <link name="knuckle3">
    <visual>
      <geometry>
        <box size="0.018 0.0095 0.031"/>
      </geometry>
      <origin xyz="0 0 0"/>
      <material name="blue">
      </material>
    </visual>
    <collision>
      <geometry>
        <box size="0.018 0.0095 0.031"/>
      </geometry>
    </collision>
    <inertial>
      <mass value="1"/>
      <inertia ixx="0.4" ixy="0.0" ixz="0.0" iyy="0.4" iyz="0.0" izz="0.2"/>
    </inertial>
  </link>
  <joint name="palm2_to_knuckle3" type="fixed">
    <parent link="palm2"/>
    <child link="knuckle3"/>
    <origin xyz="-.0105 -.00375 0.028"/>
  </joint>
  <link name="knuckle4">
    <visual>
      <geometry>
        <box size="0.018 0.0095 0.026"/>
      </geometry>
      <origin xyz="0 0 0"/>
      <material name="blue">
      </material>
    </visual>
    <collision>
      <geometry>
        <box size="0.018 0.0095 0.026"/>
      </geometry>
    </collision>
    <inertial>
      <mass value="1"/>
      <inertia ixx="0.4" ixy="0.0" ixz="0.0" iyy="0.4" iyz="0.0" izz="0.2"/>
    </inertial>
  </link>
  <joint name="palm2_to_knuckle4" type="fixed">
    <parent link="palm2"/>
    <child link="knuckle4"/>
    <origin xyz="-.0315 -.00375 .0255"/>
  </joint>
   define fingers

  
  <link name="finger1a">
    <visual>
      <geometry>
        <box size="0.014 0.004 0.045"/>
      </geometry>
      <origin xyz="0 0 0.0225"/>
      <material name="blue">
      </material>
    </visual>
    <collision>
      <geometry>
        <box size="0.014 0.004 0.045"/>
      </geometry>
      <origin xyz="0 0 0.0225"/>
    </collision>
    <inertial>
      <mass value="1"/>
      <inertia ixx="0.4" ixy="0.0" ixz="0.0" iyy="0.4" iyz="0.0" izz="0.2"/>
    </inertial>
  </link>
  <joint name="knuckle1_to_finger1a" type="revolute">
    <axis xyz="-1 0 0"/>
    <limit effort="1000.0" lower="0.0" upper="1.5" velocity="0.5"/>
    <parent link="knuckle1"/>
    <child link="finger1a"/>
    <origin xyz="0 0 .018"/>
    <joint_properties damping="1.0" friction="0.0"/>
    <mimic joint="pris2" multiplier="79.93" offset="0.29"/>
  </joint>
  <link name="finger2a">
    <visual>
      <geometry>
        <box size="0.014 0.004 0.045"/>
      </geometry>
      <origin xyz="0 0 0.0225"/>
      <material name="blue">
      </material>
    </visual>
    <collision>
      <geometry>
        <box size="0.014 0.004 0.045"/>
      </geometry>
      <origin xyz="0 0 0.0225"/>
    </collision>
    <inertial>
      <mass value="1"/>
      <inertia ixx="0.4" ixy="0.0" ixz="0.0" iyy="0.4" iyz="0.0" izz="0.2"/>
    </inertial>
  </link>
  <joint name="knuckle2_to_finger2a" type="revolute">
    <axis xyz="-1 0 0"/>
    <limit effort="1000.0" lower="0.0" upper="1.5" velocity="0.5"/>
    <parent link="knuckle2"/>
    <child link="finger2a"/>
    <origin xyz="0 0 .02"/>
    <joint_properties damping="1.0" friction="0.0"/>
    <mimic joint="pris4" multiplier="79.93" offset="0.29"/>
  </joint>
  <link name="finger3a">
    <visual>
      <geometry>
        <box size="0.014 0.004 0.045"/>
      </geometry>
      <origin xyz="0 0 0.0225"/>
      <material name="blue">
      </material>
    </visual>
    <collision>
      <geometry>
        <box size="0.014 0.004 0.045"/>
      </geometry>
      <origin xyz="0 0 0.0225"/>
    </collision>
    <inertial>
      <mass value="1"/>
      <inertia ixx="0.4" ixy="0.0" ixz="0.0" iyy="0.4" iyz="0.0" izz="0.2"/>
    </inertial>
  </link>
  <joint name="knuckle3_to_finger3a" type="revolute">
    <axis xyz="-1 0 0"/>
    <limit effort="1000.0" lower="0.0" upper="1.5" velocity="0.5"/>
    <parent link="knuckle3"/>
    <child link="finger3a"/>
    <origin xyz="0 0 .03"/>
    <joint_properties damping="1.0" friction="0.0"/>
    <mimic joint="pris6" multiplier="79.93" offset="0.29"/>
  </joint>
  <link name="finger4a">
    <visual>
      <geometry>
        <box size="0.014 0.004 0.045"/>
      </geometry>
      <origin xyz="0 0 0.0225"/>
      <material name="blue">
      </material>
    </visual>
    <collision>
      <geometry>
        <box size="0.014 0.004 0.045"/>
      </geometry>
      <origin xyz="0 0 0.0225"/>
    </collision>
    <inertial>
      <mass value="1"/>
      <inertia ixx="0.4" ixy="0.0" ixz="0.0" iyy="0.4" iyz="0.0" izz="0.2"/>
    </inertial>
  </link>
  <joint name="knuckle4_to_finger4a" type="revolute">
    <axis xyz="-1 0 0"/>
    <limit effort="1000.0" lower="0.0" upper="1.5" velocity="0.5"/>
    <parent link="knuckle4"/>
    <child link="finger4a"/>
    <origin xyz="0 0 .03"/>
    <joint_properties damping="1.0" friction="0.0"/>
    <mimic joint="pris8" multiplier="79.93" offset="0.29"/>
  </joint>
  <link name="finger1b">
    <visual>
      <geometry>
        <box size="0.016 0.004 0.03"/>
      </geometry>
      <origin xyz="0 0 0.015"/>
      <material name="blue">
      </material>
    </visual>
    <collision>
      <geometry>
        <box size="0.016 0.004 0.03"/>
      </geometry>
      <origin xyz="0 0 0.015"/>
    </collision>
    <inertial>
      <mass value="1"/>
      <inertia ixx="0.4" ixy="0.0" ixz="0.0" iyy="0.4" iyz="0.0" izz="0.2"/>
    </inertial>
  </link>
  <joint name="finger1a_to_finger1b" type="revolute">
    <axis xyz="-1 0 0"/>
    <limit effort="1000.0" lower="0.0" upper="1.5" velocity="0.5"/>
    <parent link="finger1a"/>
    <child link="finger1b"/>
    <origin xyz="0 0 0.045"/>
    <mimic joint="pris3" multiplier="79.64" offset="0.29"/>
    <joint_properties damping="1.0" friction="0.0"/>
  </joint>
  <link name="finger2b">
    <visual>
      <geometry>
        <box size="0.016 0.004 0.03"/>
      </geometry>
      <origin xyz="0 0 0.015"/>
      <material name="blue">
      </material>
    </visual>
    <collision>
      <geometry>
        <box size="0.016 0.004 0.03"/>
      </geometry>
      <origin xyz="0 0 0.015"/>
    </collision>
    <inertial>
      <mass value="1"/>
      <inertia ixx="0.4" ixy="0.0" ixz="0.0" iyy="0.4" iyz="0.0" izz="0.2"/>
    </inertial>
  </link>
  <joint name="finger2a_to_finger2b" type="revolute">
    <axis xyz="-1 0 0"/>
    <limit effort="1000.0" lower="0.0" upper="1.5" velocity="0.5"/>
    <parent link="finger2a"/>
    <child link="finger2b"/>
    <origin xyz="0 0 0.045"/>
    <joint_properties damping="1.0" friction="0.0"/>
    <mimic joint="pris5" multiplier="79.64" offset="0.29"/>
  </joint>
  <link name="finger3b">
    <visual>
      <geometry>
        <box size="0.016 0.004 0.03"/>
      </geometry>
      <origin xyz="0 0 0.015"/>
      <material name="blue">
      </material>
    </visual>
    <collision>
      <geometry>
        <box size="0.016 0.004 0.03"/>
      </geometry>
      <origin xyz="0 0 0.015"/>
    </collision>
    <inertial>
      <mass value="1"/>
      <inertia ixx="0.4" ixy="0.0" ixz="0.0" iyy="0.4" iyz="0.0" izz="0.2"/>
    </inertial>
  </link>
  <joint name="finger3a_to_finger3b" type="revolute">
    <axis xyz="-1 0 0"/>
    <limit effort="1000.0" lower="0.0" upper="1.5" velocity="0.5"/>
    <parent link="finger3a"/>
    <child link="finger3b"/>
    <origin xyz="0 0 0.045"/>
    <joint_properties damping="1.0" friction="0.0"/>
    <mimic joint="pris7" multiplier="79.64" offset="0.29"/>
  </joint>
  <link name="finger4b">
    <visual>
      <geometry>
        <box size="0.016 0.004 0.03"/>
      </geometry>
      <origin xyz="0 0 0.015"/>
      <material name="blue">
      </material>
    </visual>
    <collision>
      <geometry>
        <box size="0.016 0.004 0.03"/>
      </geometry>
      <origin xyz="0 0 0.015"/>
    </collision>
    <inertial>
      <mass value="1"/>
      <inertia ixx="0.4" ixy="0.0" ixz="0.0" iyy="0.4" iyz="0.0" izz="0.2"/>
    </inertial>
  </link>
  <joint name="finger4a_to_finger4b" type="revolute">
    <axis xyz="-1 0 0"/>
    <limit effort="1000.0" lower="0.0" upper="1.5" velocity="0.5"/>
    <parent link="finger4a"/>
    <child link="finger4b"/>
    <origin xyz="0 0 0.045"/>
    <joint_properties damping="1.0" friction="0.0"/>
    <mimic joint="pris9" multiplier="79.64" offset="0.29"/>
  </joint>
  <link name="finger1c">
    <visual>
      <geometry>
        <box size="0.02 0.01 0.025"/>
      </geometry>
      <origin xyz="0 0 0.0125"/>
      <material name="black">
      </material>
    </visual>
    <collision>
      <geometry>
        <box size="0.02 0.01 0.025"/>
      </geometry>
      <origin xyz="0 0 0.0125"/>
    </collision>
    <inertial>
      <mass value="1"/>
      <inertia ixx="0.4" ixy="0.0" ixz="0.0" iyy="0.4" iyz="0.0" izz="0.2"/>
    </inertial>
  </link>
  <joint name="finger1b_to_finger1c" type="revolute">
    <parent link="finger1b"/>
    <child link="finger1c"/>
    <origin xyz="0 0 0.03"/>
    <axis xyz="-1 0 0"/>
    <limit effort="1000.0" lower="0" upper="1.5" velocity="0.5"/>
    <mimic joint="pris3" multiplier="68.88" offset="0.16"/>
  </joint>
  <link name="finger2c">
    <visual>
      <geometry>
        <box size="0.02 0.01 0.025"/>
      </geometry>
      <origin xyz="0 0 0.0125"/>
      <material name="black">
      </material>
    </visual>
    <collision>
      <geometry>
        <box size="0.02 0.01 0.025"/>
      </geometry>
      <origin xyz="0 0 0.03"/>
    </collision>
    <inertial>
      <mass value="1"/>
      <inertia ixx="0.4" ixy="0.0" ixz="0.0" iyy="0.4" iyz="0.0" izz="0.2"/>
    </inertial>
  </link>
  <joint name="finger2b_to_finger2c" type="revolute">
    <parent link="finger2b"/>
    <child link="finger2c"/>
    <origin xyz="0 0 0.03"/>
    <axis xyz="-1 0 0"/>
    <limit effort="1000.0" lower="0" upper="1.5" velocity="0.5"/>
    <mimic joint="pris5" multiplier="68.88" offset="0.16"/>
  </joint>
  <link name="finger3c">
    <visual>
      <geometry>
        <box size="0.02 0.01 0.025"/>
      </geometry>
      <origin xyz="0 0 0.0125"/>
      <material name="black">
      </material>
      <inertial>
        <mass value="10"/>
        <inertia ixx="0.4" ixy="0.0" ixz="0.0" iyy="0.4" iyz="0.0" izz="0.2"/>
      </inertial>
    </visual>
    <collision>
      <geometry>
        <box size="0.02 0.01 0.025"/>
      </geometry>
      <origin xyz="0 0 0.0125"/>
    </collision>
    <inertial>
      <mass value="1"/>
      <inertia ixx="0.4" ixy="0.0" ixz="0.0" iyy="0.4" iyz="0.0" izz="0.2"/>
    </inertial>
  </link>
  <joint name="finger3b_to_finger3c" type="revolute">
    <parent link="finger3b"/>
    <child link="finger3c"/>
    <origin xyz="0 0 0.03"/>
    <axis xyz="-1 0 0"/>
    <limit effort="1000.0" lower="0" upper="1.5" velocity="0.5"/>
    <mimic joint="pris7" multiplier="68.88" offset="0.16"/>
  </joint>
  <link name="finger4c">
    <visual>
      <geometry>
        <box size="0.02 0.01 0.025"/>
      </geometry>
      <origin xyz="0 0 0.0125"/>
      <material name="black">
      </material>
    </visual>
    <collision>
      <geometry>
        <box size="0.02 0.01 0.025"/>
      </geometry>
      <origin xyz="0 0 0.0125"/>
    </collision>
    <inertial>
      <mass value="1"/>
      <inertia ixx="0.4" ixy="0.0" ixz="0.0" iyy="0.4" iyz="0.0" izz="0.2"/>
    </inertial>
  </link>
  <joint name="finger4b_to_finger4c" type="revolute">
    <parent link="finger4b"/>
    <child link="finger4c"/>
    <origin xyz="0 0 0.03"/>
    <axis xyz="-1 0 0"/>
    <limit effort="1000.0" lower="0" upper="1.5" velocity="0.5"/>
    <mimic joint="pris9" multiplier="68.88" offset="0.19"/>
  </joint>
  <link name="thumb">
    <visual>
      <geometry>
        <box size="0.019 0.03 0.002"/>
      </geometry>
      <origin xyz="0 0.015 0"/>
      <material name="blue">
      </material>
    </visual>
    <collision>
      <geometry>
        <box size="0.019 0.03 0.002"/>
      </geometry>
      <origin xyz="0 0.015 0"/>
    </collision>
    <inertial>
      <mass value="1"/>
      <inertia ixx="0.4" ixy="0.0" ixz="0.0" iyy="0.4" iyz="0.0" izz="0.2"/>
    </inertial>
  </link>
  <joint name="palm1_to_thumb" type="revolute">
    <axis xyz="0 0 -1"/>
    <limit effort="1000.0" lower="0" upper="1.5" velocity="0.5"/>
    <parent link="palm1"/>
    <child link="thumb"/>
    <origin rpy=" 0 0.279 1.57 " xyz="-.045 -.01 0"/>
    <joint_properties damping="1.0" friction="0.0"/>
    <mimic joint="pris0" multiplier="83.5" offset="0.62"/>
  </joint>
  <link name="thumb2">
    <visual>
      <geometry>
        <box size="0.006 0.03 0.005"/>
      </geometry>
      <origin xyz="0 .015 0"/>
      <material name="blue">
      </material>
    </visual>
    <collision>
      <geometry>
        <box size="0.006 0.03 0.005"/>
      </geometry>
      <origin xyz="0 .015 0"/>
    </collision>
    <inertial>
      <mass value="1"/>
      <inertia ixx="0.4" ixy="0.0" ixz="0.0" iyy="0.4" iyz="0.0" izz="0.2"/>
    </inertial>
  </link>
  <joint name="thumb_to_thumb2" type="revolute">
    <axis xyz="1 0 0"/>
    <limit effort="1000.0" lower="0.0" upper="1.5" velocity="0.5"/>
    <parent link="thumb"/>
    <child link="thumb2"/>
    <origin xyz="0 0.045 -.005"/>
    <joint_properties damping="1.0" friction="0.0"/>
    <mimic joint="pris1" multiplier="56.5" offset="0.63"/>
  </joint>
  <link name="thumb_tip">
    <visual>
      <geometry>
        <box size="0.02 0.025 0.01"/>
      </geometry>
      <origin xyz="0 .0125 0"/>
      <material name="black">
      </material>
    </visual>
    <collision>
      <geometry>
        <box size="0.02 0.025 0.01"/>
      </geometry>
      <origin xyz="0 .0125 0"/>
    </collision>
    <inertial>
      <mass value="1"/>
      <inertia ixx="0.4" ixy="0.0" ixz="0.0" iyy="0.4" iyz="0.0" izz="0.2"/>
    </inertial>
  </link>
  <joint name="thumb2_to_thumb_tip" type="fixed">
    <axis xyz="1 0 0"/>
    <parent link="thumb2"/>
    <child link="thumb_tip"/>
    <origin rpy="0.698 0 0" xyz="0 0.03 0"/>
  </joint>
  <link name="motor0">
    <visual>
      <geometry>
        <box size="0.016 0.035 0.02"/>
      </geometry>
      <origin xyz="0 .02 0"/>
      <material name="black">
      </material>
    </visual>
    <collision>
      <geometry>
        <box size="0.016 0.035 0.02"/>
      </geometry>
      <origin xyz="0 .02 0"/>
    </collision>
    <inertial>
      <mass value="1"/>
      <inertia ixx="0.4" ixy="0.0" ixz="0.0" iyy="0.4" iyz="0.0" izz="0.2"/>
    </inertial>
  </link>
  <joint name="palm1_to_motor0" type="fixed">
    <axis xyz="1 0 0"/>
    <parent link="palm1"/>
    <child link="motor0"/>
    <origin rpy="1.57 -1.2945 0" xyz="0 -.0145 -.015"/>
  </joint>
  <link name="pris0">
    <visual>
      <geometry>
        <box size="0.005 0.005 0.025"/>
      </geometry>
      <origin xyz="0 0 0"/>
      <material name="black">
      </material>
    </visual>
    <inertial>
      <mass value="1"/>
      <inertia ixx="0.4" ixy="0.0" ixz="0.0" iyy="0.4" iyz="0.0" izz="0.2"/>
    </inertial>
  </link>
  <joint name="pris0" type="prismatic">
    <axis xyz="0 0 -1"/>
    <limit effort="1000.0" lower="0.0" upper="0.02" velocity="0.1"/>
    <parent link="motor0"/>
    <child link="pris0"/>
    <origin rpy="1.57 0 0" xyz="0 .03 0"/>
  </joint>
  <link name="motor1">
    <visual>
      <geometry>
        <box size="0.016 0.035 0.02"/>
      </geometry>
      <origin xyz="0 .02 0"/>
      <material name="black">
      </material>
    </visual>
    <collision>
      <geometry>
        <box size="0.016 0.035 0.02"/>
      </geometry>
      <origin xyz="0 .02 0"/>
    </collision>
    <inertial>
      <mass value="1"/>
      <inertia ixx="0.4" ixy="0.0" ixz="0.0" iyy="0.4" iyz="0.0" izz="0.2"/>
    </inertial>
  </link>
  <joint name="thumb_to_motor1" type="fixed">
    <axis xyz="1 0 0"/>
    <parent link="thumb"/>
    <child link="motor1"/>
    <origin rpy="0 0 0" xyz="0 -.0145 -.01"/>
  </joint>
  <link name="pris1">
    <visual>
      <geometry>
        <box size="0.005 0.005 0.025"/>
      </geometry>
      <origin xyz="0 0 0"/>
      <material name="black">
      </material>
    </visual>
    <inertial>
      <mass value="1"/>
      <inertia ixx="0.4" ixy="0.0" ixz="0.0" iyy="0.4" iyz="0.0" izz="0.2"/>
    </inertial>
  </link>
  <joint name="pris1" type="prismatic">
    <axis xyz="0 0 -1"/>
    <limit effort="1000.0" lower="0.0" upper="0.02" velocity="0.1"/>
    <parent link="motor1"/>
    <child link="pris1"/>
    <origin rpy="1.57 0 0" xyz="0 .03 0"/>
  </joint>
  <link name="motor2">
    <visual>
      <geometry>
        <box size="0.016 0.035 0.02"/>
      </geometry>
      <origin xyz="0 .02 0"/>
      <material name="black">
      </material>
    </visual>
    <collision>
      <geometry>
        <box size="0.016 0.035 0.02"/>
      </geometry>
      <origin xyz="0 .02 0"/>
    </collision>
    <inertial>
      <mass value="1"/>
      <inertia ixx="0.4" ixy="0.0" ixz="0.0" iyy="0.4" iyz="0.0" izz="0.2"/>
    </inertial>
  </link>
  <joint name="knuckle1_to_motor2" type="fixed">
    <axis xyz="1 0 0"/>
    <parent link="knuckle1"/>
    <child link="motor2"/>
    <origin rpy="1.57 0 0" xyz="0 -.0145 -.045"/>
  </joint>
  <link name="pris2">
    <visual>
      <geometry>
        <box size="0.005 0.005 0.025"/>
      </geometry>
      <origin xyz="0 0 0"/>
      <material name="black">
      </material>
    </visual>
    <inertial>
      <mass value="1"/>
      <inertia ixx="0.4" ixy="0.0" ixz="0.0" iyy="0.4" iyz="0.0" izz="0.2"/>
    </inertial>
  </link>
  <joint name="pris2" type="prismatic">
    <axis xyz="0 0 -1"/>
    <limit effort="1000.0" lower="0.0" upper="0.02" velocity="0.1"/>
    <parent link="motor2"/>
    <child link="pris2"/>
    <origin rpy="1.57 0 0" xyz="0 .03 0"/>
  </joint>
  <link name="motor3">
    <visual>
      <geometry>
        <box size="0.016 0.035 0.02"/>
      </geometry>
      <origin xyz="0 .02 0"/>
      <material name="black">
      </material>
    </visual>
    <collision>
      <geometry>
        <box size="0.016 0.035 0.02"/>
      </geometry>
      <origin xyz="0 .02 0"/>
    </collision>
    <inertial>
      <mass value="1"/>
      <inertia ixx="0.4" ixy="0.0" ixz="0.0" iyy="0.4" iyz="0.0" izz="0.2"/>
    </inertial>
  </link>
  <joint name="motor3_to_finger1a" type="fixed">
    <axis xyz="1 0 0"/>
    <parent link="finger1a"/>
    <child link="motor3"/>
    <origin rpy="1.57 0 0" xyz="0 -.0145 .01"/>
  </joint>
  <link name="pris3">
    <visual>
      <geometry>
        <box size="0.005 0.005 0.025"/>
      </geometry>
      <origin xyz="0 0 0"/>
      <material name="black">
      </material>
    </visual>
    <inertial>
      <mass value="1"/>
      <inertia ixx="0.4" ixy="0.0" ixz="0.0" iyy="0.4" iyz="0.0" izz="0.2"/>
    </inertial>
  </link>
  <joint name="pris3" type="prismatic">
    <axis xyz="0 0 -1"/>
    <limit effort="1000.0" lower="0.0" upper="0.02" velocity="0.1"/>
    <parent link="motor3"/>
    <child link="pris3"/>
    <origin rpy="1.57 0 0" xyz="0 .03 0"/>
  </joint>
  <link name="motor4">
    <visual>
      <geometry>
        <box size="0.016 0.035 0.02"/>
      </geometry>
      <origin xyz="0 .02 0"/>
      <material name="black">
      </material>
    </visual>
    <collision>
      <geometry>
        <box size="0.016 0.035 0.02"/>
      </geometry>
      <origin xyz="0 .02 0"/>
    </collision>
    <inertial>
      <mass value="1"/>
      <inertia ixx="0.4" ixy="0.0" ixz="0.0" iyy="0.4" iyz="0.0" izz="0.2"/>
    </inertial>
  </link>
  <joint name="knuckle2_to_motor4" type="fixed">
    <axis xyz="1 0 0"/>
    <parent link="knuckle2"/>
    <child link="motor4"/>
    <origin rpy="1.57 0 0" xyz="0 -.0145 -.045"/>
  </joint>
  <link name="pris4">
    <visual>
      <geometry>
        <box size="0.005 0.005 0.025"/>
      </geometry>
      <origin xyz="0 0 0"/>
      <material name="black">
      </material>
    </visual>
    <inertial>
      <mass value="1"/>
      <inertia ixx="0.4" ixy="0.0" ixz="0.0" iyy="0.4" iyz="0.0" izz="0.2"/>
    </inertial>
  </link>
  <joint name="pris4" type="prismatic">
    <axis xyz="0 0 -1"/>
    <limit effort="1000.0" lower="0.0" upper="0.02" velocity="0.1"/>
    <parent link="motor4"/>
    <child link="pris4"/>
    <origin rpy="1.57 0 0" xyz="0 .03 0"/>
  </joint>
  <link name="motor5">
    <visual>
      <geometry>
        <box size="0.016 0.035 0.02"/>
      </geometry>
      <origin xyz="0 .02 0"/>
      <material name="black">
      </material>
    </visual>
    <collision>
      <geometry>
        <box size="0.016 0.035 0.02"/>
      </geometry>
      <origin xyz="0 .02 0"/>
    </collision>
    <inertial>
      <mass value="1"/>
      <inertia ixx="0.4" ixy="0.0" ixz="0.0" iyy="0.4" iyz="0.0" izz="0.2"/>
    </inertial>
  </link>
  <joint name="motor5_to_finger2a" type="fixed">
    <axis xyz="1 0 0"/>
    <parent link="finger2a"/>
    <child link="motor5"/>
    <origin rpy="1.57 0 0" xyz="0 -.0145 .01"/>
  </joint>
  <link name="pris5">
    <visual>
      <geometry>
        <box size="0.005 0.005 0.025"/>
      </geometry>
      <origin xyz="0 0 0"/>
      <material name="black">
      </material>
    </visual>
    <inertial>
      <mass value="1"/>
      <inertia ixx="0.4" ixy="0.0" ixz="0.0" iyy="0.4" iyz="0.0" izz="0.2"/>
    </inertial>
  </link>
  <joint name="pris5" type="prismatic">
    <axis xyz="0 0 -1"/>
    <limit effort="1000.0" lower="0.0" upper="0.02" velocity="0.1"/>
    <parent link="motor5"/>
    <child link="pris5"/>
    <origin rpy="1.57 0 0" xyz="0 .03 0"/>
  </joint>
  <link name="motor6">
    <visual>
      <geometry>
        <box size="0.016 0.035 0.02"/>
      </geometry>
      <origin xyz="0 .02 0"/>
      <material name="black">
      </material>
    </visual>
    <collision>
      <geometry>
        <box size="0.016 0.035 0.02"/>
      </geometry>
      <origin xyz="0 .02 0"/>
    </collision>
    <inertial>
      <mass value="1"/>
      <inertia ixx="0.4" ixy="0.0" ixz="0.0" iyy="0.4" iyz="0.0" izz="0.2"/>
    </inertial>
  </link>
  <joint name="knuckle3_to_motor6" type="fixed">
    <axis xyz="1 0 0"/>
    <parent link="knuckle3"/>
    <child link="motor6"/>
    <origin rpy="1.57 0 0" xyz="0 -.0145 -.045"/>
  </joint>
  <link name="pris6">
    <visual>
      <geometry>
        <box size="0.005 0.005 0.025"/>
      </geometry>
      <origin xyz="0 0 0"/>
      <material name="black">
      </material>
    </visual>
    <inertial>
      <mass value="1"/>
      <inertia ixx="0.4" ixy="0.0" ixz="0.0" iyy="0.4" iyz="0.0" izz="0.2"/>
    </inertial>
  </link>
  <joint name="pris6" type="prismatic">
    <axis xyz="0 0 -1"/>
    <limit effort="1000.0" lower="0.0" upper="0.02" velocity="0.1"/>
    <parent link="motor6"/>
    <child link="pris6"/>
    <origin rpy="1.57 0 0" xyz="0 .03 0"/>
  </joint>
  <link name="motor7">
    <visual>
      <geometry>
        <box size="0.016 0.035 0.02"/>
      </geometry>
      <origin xyz="0 .02 0"/>
      <material name="black">
      </material>
    </visual>
    <collision>
      <geometry>
        <box size="0.016 0.035 0.02"/>
      </geometry>
      <origin xyz="0 .02 0"/>
    </collision>
    <inertial>
      <mass value="1"/>
      <inertia ixx="0.4" ixy="0.0" ixz="0.0" iyy="0.4" iyz="0.0" izz="0.2"/>
    </inertial>
  </link>
  <joint name="motor7_to_finger3a" type="fixed">
    <axis xyz="1 0 0"/>
    <parent link="finger3a"/>
    <child link="motor7"/>
    <origin rpy="1.57 0 0" xyz="0 -.0145 .01"/>
  </joint>
  <link name="pris7">
    <visual>
      <geometry>
        <box size="0.005 0.005 0.025"/>
      </geometry>
      <origin xyz="0 0 0"/>
      <material name="black">
      </material>
    </visual>
    <inertial>
      <mass value="1"/>
      <inertia ixx="0.4" ixy="0.0" ixz="0.0" iyy="0.4" iyz="0.0" izz="0.2"/>
    </inertial>
  </link>
  <joint name="pris7" type="prismatic">
    <axis xyz="0 0 -1"/>
    <limit effort="1000.0" lower="0.0" upper="0.02" velocity="0.1"/>
    <parent link="motor7"/>
    <child link="pris7"/>
    <origin rpy="1.57 0 0" xyz="0 .03 0"/>
  </joint>
  <link name="motor8">
    <visual>
      <geometry>
        <box size="0.016 0.035 0.02"/>
      </geometry>
      <origin xyz="0 .02 0"/>
      <material name="black">
      </material>
    </visual>
    <collision>
      <geometry>
        <box size="0.016 0.035 0.02"/>
      </geometry>
      <origin xyz="0 .02 0"/>
    </collision>
    <inertial>
      <mass value="1"/>
      <inertia ixx="0.4" ixy="0.0" ixz="0.0" iyy="0.4" iyz="0.0" izz="0.2"/>
    </inertial>
  </link>
  <joint name="knuckle4_to_motor8" type="fixed">
    <axis xyz="1 0 0"/>
    <parent link="knuckle4"/>
    <child link="motor8"/>
    <origin rpy="1.57 0 0" xyz="0 -.0145 -.045"/>
  </joint>
  <link name="pris8">
    <visual>
      <geometry>
        <box size="0.005 0.005 0.025"/>
      </geometry>
      <origin xyz="0 0 0"/>
      <material name="black">
      </material>
    </visual>
    <inertial>
      <mass value="1"/>
      <inertia ixx="0.4" ixy="0.0" ixz="0.0" iyy="0.4" iyz="0.0" izz="0.2"/>
    </inertial>
  </link>
  <joint name="pris8" type="prismatic">
    <axis xyz="0 0 -1"/>
    <limit effort="1000.0" lower="0.0" upper="0.02" velocity="0.1"/>
    <parent link="motor8"/>
    <child link="pris8"/>
    <origin rpy="1.57 0 0" xyz="0 .03 0"/>
  </joint>
  <link name="motor9">
    <visual>
      <geometry>
        <box size="0.016 0.035 0.02"/>
      </geometry>
      <origin xyz="0 .02 0"/>
      <material name="black">
      </material>
    </visual>
    <collision>
      <geometry>
        <box size="0.016 0.035 0.02"/>
      </geometry>
      <origin xyz="0 .02 0"/>
    </collision>
    <inertial>
      <mass value="1"/>
      <inertia ixx="0.4" ixy="0.0" ixz="0.0" iyy="0.4" iyz="0.0" izz="0.2"/>
    </inertial>
  </link>
  <joint name="motor9_to_finger4a" type="fixed">
    <axis xyz="1 0 0"/>
    <parent link="finger4a"/>
    <child link="motor9"/>
    <origin rpy="1.57 0 0" xyz="0 -.0145 .01"/>
  </joint>
  <link name="pris9">
    <visual>
      <geometry>
        <box size="0.005 0.005 0.025"/>
      </geometry>
      <origin xyz="0 0 0"/>
      <material name="black">
      </material>
    </visual>
    <inertial>
      <mass value="1"/>
      <inertia ixx="0.4" ixy="0.0" ixz="0.0" iyy="0.4" iyz="0.0" izz="0.2"/>
    </inertial>
  </link>
  <joint name="pris9" type="prismatic">
    <axis xyz="0 0 -1"/>
    <limit effort="1000.0" lower="0.0" upper=".02" velocity="0.1"/>
    <parent link="motor9"/>
    <child link="pris9"/>
    <origin rpy="1.57 0 0" xyz="0 .03 0"/>
  </joint>
  <!-- total ur_ar10 system world -->
  <link name="world"/>
  <joint name="world_joint" type="fixed">
    <parent link="world"/>
    <child link="torso_body_link"/>
    <origin rpy="0.0 0.0 0.0" xyz="0.0 0.0 0.0"/>
  </joint>
  <!-- torso body-->
  <link name="torso_body_link">
    <visual>
      <geometry>
        <box size="0.22 0.22 0.5"/>
      </geometry>
      <origin rpy="0 0 0" xyz="0 0 0.25"/>
      <material name="LightGrey">
        <color rgba="0.7 0.7 0.7 1.0"/>
      </material>
    </visual>
    <collision>
      <geometry>
        <box size="0.22 0.22 0.5"/>
      </geometry>
    </collision>
    <inertial>
      <!--mass: kg, inertia: using meshlab program -->
      <origin rpy="0 0 0" xyz="0 0 0"/>
      <mass value="20"/>
      <inertia ixx="0.5" ixy="0" ixz="0" iyy="0.6" iyz="0" izz="0.3"/>
    </inertial>
  </link>
  <joint name="torso_body_joint" type="fixed">
    <origin rpy="0.0 0.0 0.0" xyz="0.0 0.0 0.5"/>
    <parent link="world"/>
    <child link="base_link"/>
  </joint>
  <!-- Kinect mount -->
  <link name="mount_link">
    <visual>
      <geometry>
        <box size="0.20 0.08 0.01"/>
        <!--mesh filename="$(find common_sensors)/urdf/stl/MountCamera.stl"/-->
      </geometry>
      <origin rpy="0 1.57 0" xyz="0 0 -0.06"/>
      <material name="LightGrey">
        <color rgba="0.5 0.3 0.3 1.0"/>
      </material>
    </visual>
    <collision>
      <geometry>
        <box size="0.20 0.08 0.01"/>
      </geometry>
    </collision>
  </link>
  <joint name="mount_joint" type="fixed">
    <origin rpy="0.0 0.0 0.0" xyz="0.0 0.0 0.0"/>
    <parent link="ee_link"/>
    <child link="mount_link"/>
  </joint>
  <link name="kinect_link">
    <collision>
      <origin rpy="0.0 0.0 0.0" xyz="0 0 0"/>
      <geometry>
        <box size="0.05 0.2 0.05"/>
      </geometry>
    </collision>
    <visual>
      <origin rpy="0.0 0.0 0.0" xyz="0 0 0"/>
      <geometry>
        <box size="0.05 0.2 0.05"/>
      </geometry>
      <material name="kinect_gray">
        <color rgba="0.2 0.2 0.2 1.0"/>
      </material>
    </visual>
    <inertial>
      <mass value="0.1"/>
      <origin rpy="0.0 0.0 0.0" xyz="0 0 0"/>
      <inertia ixx="0.001" ixy="0.0" ixz="0.0" iyy="0.001" iyz="0.0" izz="0.001"/>
    </inertial>
  </link>
  <!-- the above displays a box meant to imply kinect -->
  <!-- now set the position/orientation of the above box -->
  <joint name="kinect_joint" type="fixed">
    <axis xyz="0.0 1.0 0.0"/>
    <origin rpy="0.0 1.2 0.0" xyz="0.2 0.0 0.9"/>
    <parent link="torso"/>
    <!-- robot torso -->
    <child link="kinect_link"/>
  </joint>
  <joint name="camera_optical_joint" type="fixed">
    <origin rpy="-1.57079632679 0.0 -1.57079632679" xyz="0.0 0.0 0.0"/>
    <parent link="kinect_link"/>
    <child link="camera_link_optical"/>
  </joint>
  <link name="camera_link_optical">        
    </link>
  <!-- add kinect snesor emulation -->
  <gazebo reference="kinect_link">
    <sensor name="camera_1" type="depth">
      <always_on>1</always_on>
      <visualize>true</visualize>
      <camera>
        <horizontal_fov>1.047</horizontal_fov>
        <image>
          <width>640</width>
          <height>480</height>
          <format>R8G8B8</format>
        </image>
        <depth_camera>
                </depth_camera>
        <clip>
          <near>0.1</near>
          <far>100</far>
        </clip>
      </camera>
      <plugin filename="libgazebo_ros_openni_kinect.so" name="camera_controller">
        <alwaysOn>true</alwaysOn>
        <updateRate>10.0</updateRate>
        <cameraName>kinect</cameraName>
        <frameName>camera_link_optical</frameName>
        <imageTopicName>rgb/image_raw</imageTopicName>
        <depthImageTopicName>depth/image_raw</depthImageTopicName>
        <pointCloudTopicName>depth/points</pointCloudTopicName>
        <cameraInfoTopicName>rgb/camera_info</cameraInfoTopicName>
        <depthImageCameraInfoTopicName>depth/camera_info</depthImageCameraInfoTopicName>
        <pointCloudCutoff>0.4</pointCloudCutoff>
        <hackBaseline>0.07</hackBaseline>
        <distortionK1>0.0</distortionK1>
        <distortionK2>0.0</distortionK2>
        <distortionK3>0.0</distortionK3>
        <distortionT1>0.0</distortionT1>
        <distortionT2>0.0</distortionT2>
        <CxPrime>0.0</CxPrime>
        <Cx>0.0</Cx>
        <Cy>0.0</Cy>
        <focalLength>0.0</focalLength>
      </plugin>
    </sensor>
  </gazebo>
</robot>

